Workbook

Sheet task1
A1: Master reference table containing restaurant identity details mapped to their respective operational regions.
A3: Restaurant ID | B3: Restaurant Name | C3: Operational City
A4: 101 | B4: La Pinoz | C4: Vadodara
A5: 102 | B5: McDonalds | C5: Ahmedabad
A6: 103 | B6: Subway | C6: Surat
A7: 104 | B7: Burger King | C7: Rajkot
A8: 105 | B8: Pizza Hut | C8: Vadodara
A9: 106 | B9: KFC | C9: Ahmedabad

Sheet Task 1, 2 & 3 - Cleaned Data
A1: Task 1, 2 & 3: Cleaned main order tracking workspace containing VLOOKUP mappings and day extraction transforms.
A3: Order ID | B3: Delivery Date | C3: Restaurant ID | D3: Restaurant Name (VLOOKUP) | E3: Day of Week | F3: City | G3: Delivery Partner | H3: Order Amount | I3: Delivery Charges | J3: Delivery Time (Mins)
A4: ZOM-ORD-001 | B4: 46176 | C4: 102 | D4: =VLOOKUP(C4, task1!A4:B9, 2, FALSE) -> McDonalds | E4: =TEXT(B4, "DDDD") -> Wednesday | F4: Rajkot | G4: Zomato | H4: 198 | I4: 68 | J4: 50
A5: ZOM-ORD-002 | B5: 46180 | C5: 102 | D5: =VLOOKUP(C5, task1!A4:B9, 2, FALSE) -> McDonalds | E5: =TEXT(B5, "DDDD") -> Sunday | F5: Surat | G5: Unassigned | H5: 597 | I5: 64 | J5: 51
A6: ZOM-ORD-003 | B6: 46180 | C6: 105 | D6: =VLOOKUP(C6, task1!A4:B9, 2, FALSE) -> Pizza Hut | E6: =TEXT(B6, "DDDD") -> Sunday | F6: Rajkot | G6: Swiggy | H6: 1358 | I6: 61 | J6: 20
A7: ZOM-ORD-004 | B7: 46190 | C7: 106 | D7: =VLOOKUP(C7, task1!A4:B9, 2, FALSE) -> KFC | E7: =TEXT(B7, "DDDD") -> Wednesday | F7: Surat | G7: Swiggy | H7: 1102 | I7: 64 | J7: 49
A8: ZOM-ORD-005 | B8: 46175 | C8: 106 | D8: =VLOOKUP(C8, task1!A4:B9, 2, FALSE) -> KFC | E8: =TEXT(B8, "DDDD") -> Tuesday | F8: Ahmedabad | G8: Unassigned | H8: 1465 | I8: 68 | J8: 42
A9: ZOM-ORD-006 | B9: 46190 | C9: 105 | D9: =VLOOKUP(C9, task1!A4:B9, 2, FALSE) -> Pizza Hut | E9: =TEXT(B9, "DDDD") -> Wednesday | F9: Vadodara | G9: Zomato | H9: 1008 | I9: 48 | J9: 24
A10: ZOM-ORD-007 | B10: 46178 | C10: 106 | D10: =VLOOKUP(C10, task1!A4:B9, 2, FALSE) -> KFC | E10: =TEXT(B10, "DDDD") -> Friday | F10: Vadodara | G10: Swiggy | H10: 385 | I10: 77 | J10: 50
A11: ZOM-ORD-008 | B11: 46174 | C11: 105 | D11: =VLOOKUP(C11, task1!A4:B9, 2, FALSE) -> Pizza Hut | E11: =TEXT(B11, "DDDD") -> Monday | F11: Surat | G11: Zomato | H11: 1071 | I11: 52 | J11: 41
A12: ZOM-ORD-009 | B12: 46175 | C12: 101 | D12: =VLOOKUP(C12, task1!A4:B9, 2, FALSE) -> La Pinoz | E12: =TEXT(B12, "DDDD") -> Tuesday | F12: Rajkot | G12: Zepto | H12: 331 | I12: 22 | J12: 22
A13: ZOM-ORD-010 | B13: 46185 | C13: 101 | D13: =VLOOKUP(C13, task1!A4:B9, 2, FALSE) -> La Pinoz | E13: =TEXT(B13, "DDDD") -> Friday | F13: Surat | G13: Swiggy | H13: 1140 | I13: 44 | J13: 40
A14: ZOM-ORD-011 | B14: 46185 | C14: 101 | D14: =VLOOKUP(C14, task1!A4:B9, 2, FALSE) -> La Pinoz | E14: =TEXT(B14, "DDDD") -> Friday | F14: Ahmedabad | G14: Swiggy | H14: 1477 | I14: 59 | J14: 20
A15: ZOM-ORD-012 | B15: 46191 | C15: 103 | D15: =VLOOKUP(C15, task1!A4:B9, 2, FALSE) -> Subway | E15: =TEXT(B15, "DDDD") -> Thursday | F15: Rajkot | G15: Zomato | H15: 794 | I15: 54 | J15: 47
A16: ZOM-ORD-013 | B16: 46174 | C16: 101 | D16: =VLOOKUP(C16, task1!A4:B9, 2, FALSE) -> La Pinoz | E16: =TEXT(B16, "DDDD") -> Monday | F16: Rajkot | G16: Zepto | H16: 151 | I16: 47 | J16: 48
A17: ZOM-ORD-014 | B17: 46175 | C17: 103 | D17: =VLOOKUP(C17, task1!A4:B9, 2, FALSE) -> Subway | E17: =TEXT(B17, "DDDD") -> Tuesday | F17: Surat | G17: Swiggy | H17: 495 | I17: 37 | J17: 18
A18: ZOM-ORD-015 | B18: 46187 | C18: 102 | D18: =VLOOKUP(C18, task1!A4:B9, 2, FALSE) -> McDonalds | E18: =TEXT(B18, "DDDD") -> Sunday | F18: Rajkot | G18: Swiggy | H18: 695 | I18: 31 | J18: 26
A19: ZOM-ORD-016 | B19: 46185 | C19: 106 | D19: =VLOOKUP(C19, task1!A4:B9, 2, FALSE) -> KFC | E19: =TEXT(B19, "DDDD") -> Friday | F19: Rajkot | G19: Zepto | H19: 620 | I19: 37 | J19: 24
A20: ZOM-ORD-017 | B20: 46175 | C20: 102 | D20: =VLOOKUP(C20, task1!A4:B9, 2, FALSE) -> McDonalds | E20: =TEXT(B20, "DDDD") -> Tuesday | F20: Vadodara | G20: Zomato | H20: 1212 | I20: 66 | J20: 43
A21: ZOM-ORD-018 | B21: 46177 | C21: 102 | D21: =VLOOKUP(C21, task1!A4:B9, 2, FALSE) -> McDonalds | E21: =TEXT(B21, "DDDD") -> Thursday | F21: Ahmedabad | G21: Zepto | H21: 1363 | I21: 65 | J21: 40
A22: ZOM-ORD-019 | B22: 46188 | C22: 103 | D22: =VLOOKUP(C22, task1!A4:B9, 2, FALSE) -> Subway | E22: =TEXT(B22, "DDDD") -> Monday | F22: Ahmedabad | G22: Zomato | H22: 294 | I22: 54 | J22: 15
A23: ZOM-ORD-020 | B23: 46177 | C23: 102 | D23: =VLOOKUP(C23, task1!A4:B9, 2, FALSE) -> McDonalds | E23: =TEXT(B23, "DDDD") -> Thursday | F23: Surat | G23: Zepto | H23: 780 | I23: 78 | J23: 15
A24: ZOM-ORD-021 | B24: 46186 | C24: 106 | D24: =VLOOKUP(C24, task1!A4:B9, 2, FALSE) -> KFC | E24: =TEXT(B24, "DDDD") -> Saturday | F24: Rajkot | G24: Zomato | H24: 331 | I24: 55 | J24: 45
A25: ZOM-ORD-022 | B25: 46186 | C25: 103 | D25: =VLOOKUP(C25, task1!A4:B9, 2, FALSE) -> Subway | E25: =TEXT(B25, "DDDD") -> Saturday | F25: Ahmedabad | G25: Unassigned | H25: 1085 | I25: 50 | J25: 52
A26: ZOM-ORD-023 | B26: 46192 | C26: 105 | D26: =VLOOKUP(C26, task1!A4:B9, 2, FALSE) -> Pizza Hut | E26: =TEXT(B26, "DDDD") -> Friday | F26: Rajkot | G26: Swiggy | H26: 1264 | I26: 51 | J26: 30
A27: ZOM-ORD-024 | B27: 46186 | C27: 103 | D27: =VLOOKUP(C27, task1!A4:B9, 2, FALSE) -> Subway | E27: =TEXT(B27, "DDDD") -> Saturday | F27: Surat | G27: Swiggy | H27: 304 | I27: 64 | J27: 52
A28: ZOM-ORD-025 | B28: 46177 | C28: 102 | D28: =VLOOKUP(C28, task1!A4:B9, 2, FALSE) -> McDonalds | E28: =TEXT(B28, "DDDD") -> Thursday | F28: Ahmedabad | G28: Swiggy | H28: 388 | I28: 62 | J28: 51
A29: ZOM-ORD-026 | B29: 46174 | C29: 106 | D29: =VLOOKUP(C29, task1!A4:B9, 2, FALSE) -> KFC | E29: =TEXT(B29, "DDDD") -> Monday | F29: Rajkot | G29: Zepto | H29: 504 | I29: 59 | J29: 26
A30: ZOM-ORD-027 | B30: 46190 | C30: 103 | D30: =VLOOKUP(C30, task1!A4:B9, 2, FALSE) -> Subway | E30: =TEXT(B30, "DDDD") -> Wednesday | F30: Ahmedabad | G30: Zepto | H30: 1367 | I30: 46 | J30: 36
A31: ZOM-ORD-028 | B31: 46191 | C31: 106 | D31: =VLOOKUP(C31, task1!A4:B9, 2, FALSE) -> KFC | E31: =TEXT(B31, "DDDD") -> Thursday | F31: Ahmedabad | G31: Unassigned | H31: 664 | I31: 35 | J31: 26
A32: ZOM-ORD-029 | B32: 46181 | C32: 104 | D32: =VLOOKUP(C32, task1!A4:B9, 2, FALSE) -> Burger King | E32: =TEXT(B32, "DDDD") -> Monday | F32: Surat | G32: Zomato | H32: 624 | I32: 36 | J32: 29
A33: ZOM-ORD-030 | B33: 46174 | C33: 102 | D33: =VLOOKUP(C33, task1!A4:B9, 2, FALSE) -> McDonalds | E33: =TEXT(B33, "DDDD") -> Monday | F33: Ahmedabad | G33: Zepto | H33: 693 | I33: 72 | J33: 37
A34: ZOM-ORD-031 | B34: 46183 | C34: 102 | D34: =VLOOKUP(C34, task1!A4:B9, 2, FALSE) -> McDonalds | E34: =TEXT(B34, "DDDD") -> Wednesday | F34: Ahmedabad | G34: Unassigned | H34: 364 | I34: 41 | J34: 25
A35: ZOM-ORD-032 | B35: 46183 | C35: 104 | D35: =VLOOKUP(C35, task1!A4:B9, 2, FALSE) -> Burger King | E35: =TEXT(B35, "DDDD") -> Wednesday | F35: Rajkot | G35: Swiggy | H35: 1154 | I35: 73 | J35: 54
A36: ZOM-ORD-033 | B36: 46176 | C36: 102 | D36: =VLOOKUP(C36, task1!A4:B9, 2, FALSE) -> McDonalds | E36: =TEXT(B36, "DDDD") -> Wednesday | F36: Vadodara | G36: Zepto | H36: 1236 | I36: 45 | J36: 52
A37: ZOM-ORD-034 | B37: 46175 | C37: 102 | D37: =VLOOKUP(C37, task1!A4:B9, 2, FALSE) -> McDonalds | E37: =TEXT(B37, "DDDD") -> Tuesday | F37: Vadodara | G37: Zomato | H37: 261 | I37: 74 | J37: 53
A38: ZOM-ORD-035 | B38: 46176 | C38: 103 | D38: =VLOOKUP(C38, task1!A4:B9, 2, FALSE) -> Subway | E38: =TEXT(B38, "DDDD") -> Wednesday | F38: Rajkot | G38: Swiggy | H38: 846 | I38: 65 | J38: 22
A39: ZOM-ORD-036 | B39: 46189 | C39: 106 | D39: =VLOOKUP(C39, task1!A4:B9, 2, FALSE) -> KFC | E39: =TEXT(B39, "DDDD") -> Tuesday | F39: Vadodara | G39: Zomato | H39: 1177 | I39: 62 | J39: 15
A40: ZOM-ORD-037 | B40: 46183 | C40: 102 | D40: =VLOOKUP(C40, task1!A4:B9, 2, FALSE) -> McDonalds | E40: =TEXT(B40, "DDDD") -> Wednesday | F40: Ahmedabad | G40: Unassigned | H40: 1228 | I40: 23 | J40: 43
A41: ZOM-ORD-038 | B41: 46180 | C41: 102 | D41: =VLOOKUP(C41, task1!A4:B9, 2, FALSE) -> McDonalds | E41: =TEXT(B41, "DDDD") -> Sunday | F41: Vadodara | G41: Zomato | H41: 893 | I41: 73 | J41: 45
...

Sheet task4
A1: Task 4: Summary Table showing total orders and total delivery charges collected for each city using Pivot Table profiles.
A3: City | B3: Total Orders | C3: Total Delivery Charges Collected
A4: Vadodara | B4: =COUNTIF('Task 1, 2 & 3 - Cleaned Data'!F4:F73, A4) -> 14 | C4: =SUMIF('Task 1, 2 & 3 - Cleaned Data'!F4:F73, A4, 'Task 1, 2 & 3 - Cleaned Data'!I4:I73) -> 820
A5: Ahmedabad | B5: =COUNTIF('Task 1, 2 & 3 - Cleaned Data'!F4:F73, A5) -> 17 | C5: =SUMIF('Task 1, 2 & 3 - Cleaned Data'!F4:F73, A5, 'Task 1, 2 & 3 - Cleaned Data'!I4:I73) -> 848
A6: Surat | B6: =COUNTIF('Task 1, 2 & 3 - Cleaned Data'!F4:F73, A6) -> 23 | C6: =SUMIF('Task 1, 2 & 3 - Cleaned Data'!F4:F73, A6, 'Task 1, 2 & 3 - Cleaned Data'!I4:I73) -> 1166
A7: Rajkot | B7: =COUNTIF('Task 1, 2 & 3 - Cleaned Data'!F4:F73, A7) -> 16 | C7: =SUMIF('Task 1, 2 & 3 - Cleaned Data'!F4:F73, A7, 'Task 1, 2 & 3 - Cleaned Data'!I4:I73) -> 855
A8: Grand Total | B8: =SUM(B4:B7) -> 70 | C8: =SUM(C4:C7) -> 3689

Sheet task5
A1: Task 5: Operational Performance Executive Metric Dashboard
A3: FOOD DELIVERY EXECUTIVE DASHBOARD INTERACTION SUITE
A6: Total Orders Count | D6: Avg Delivery Time (Mins) | H6: Filter Slicer: City
A7: =COUNTA('Task 1, 2 & 3 - Cleaned Data'!A4:A73) -> 70 | D7: =AVERAGE('Task 1, 2 & 3 - Cleaned Data'!J4:J73) -> 35.642857 | H7: All Regions (Selected)
H8: Vadodara
H9: Ahmedabad
A10: Leaderboard: Top Restaurants by Orders | H10: Surat
H11: Rajkot
A12: Rank | B12: Restaurant Name | C12: Total Order Volume Placed
A13: 1 | B13: Subway | C13: =COUNTIF('Task 1, 2 & 3 - Cleaned Data'!D4:D73, B13) -> 12
A14: 2 | B14: McDonalds | C14: =COUNTIF('Task 1, 2 & 3 - Cleaned Data'!D4:D73, B14) -> 18
A15: 3 | B15: La Pinoz | C15: =COUNTIF('Task 1, 2 & 3 - Cleaned Data'!D4:D73, B15) -> 11
